Workbook

Sheet 員工資料
A1: 員工ID | B1: 姓名 | C1: 部門 | D1: 職級 | E1: 到職日期 | F1: 月薪(TWD) | G1: 績效評等 | H1: 年資(年) | I1: 離職日期
A2: EMP10001 | B2: 謝勝閎 | C2: 產品部 | D2: L6 | E2: 42556 | F2: 152000 | G2: C | H2: =DATEDIF(E2,TODAY(),"Y")
A3: EMP10002 | B3: 劉俊廷 | C3: 法務部 | D3: L4 | E3: 44607 | F3: 99000 | G3: C | H3: =DATEDIF(E3,TODAY(),"Y")
A4: EMP10003 | B4: 林文凱 | C4: 行銷部 | D4: L3 | E4: 42713 | F4: 83000 | G4: B | H4: =DATEDIF(E4,TODAY(),"Y") | I4: 44453
A5: EMP10004 | B5: 蔡勝閎 | C5: 法務部 | D5: L2 | E5: 41489 | F5: 49000 | G5: C | H5: =DATEDIF(E5,TODAY(),"Y")
A6: EMP10005 | B6: 邱冠霖 | C6: 行銷部 | D6: L3 | E6: 44781 | F6: 82000 | G6: A | H6: =DATEDIF(E6,TODAY(),"Y")
A7: EMP10006 | B7: 郭碩宇 | C7: 業務部 | D7: L2 | E7: 43811 | F7: 51000 | G7: C | H7: =DATEDIF(E7,TODAY(),"Y")
A8: EMP10007 | B8: 張秀蘭 | C8: 工程部 | D8: L2 | E8: 43688 | F8: 51000 | G8: A | H8: =DATEDIF(E8,TODAY(),"Y")
A9: EMP10008 | B9: 郭秀蘭 | C9: 工程部 | D9: L2 | E9: 44365 | F9: 65000 | G9: B | H9: =DATEDIF(E9,TODAY(),"Y")
A10: EMP10009 | B10: 廖志遠 | C10: 產品部 | D10: L5 | E10: 45417 | F10: 112000 | G10: B | H10: =DATEDIF(E10,TODAY(),"Y") | I10: 45657
A11: EMP10010 | B11: 邱淑惠 | C11: 工程部 | D11: L6 | E11: 42271 | F11: 159000 | G11: C | H11: =DATEDIF(E11,TODAY(),"Y")
A12: EMP10011 | B12: 蔡雅雯 | C12: 業務部 | D12: L5 | E12: 40926 | F12: 111000 | G12: B | H12: =DATEDIF(E12,TODAY(),"Y")
A13: EMP10012 | B13: 楊淑惠 | C13: 財務部 | D13: L3 | E13: 44895 | F13: 82000 | G13: C | H13: =DATEDIF(E13,TODAY(),"Y")
A14: EMP10013 | B14: 林雅婷 | C14: 業務部 | D14: L6 | E14: 41408 | F14: 153000 | G14: C | H14: =DATEDIF(E14,TODAY(),"Y")
A15: EMP10014 | B15: 曾思涵 | C15: 產品部 | D15: L4 | E15: 45259 | F15: 101000 | G15: D | H15: =DATEDIF(E15,TODAY(),"Y")
A16: EMP10015 | B16: 高子豪 | C16: 人資部 | D16: L4 | E16: 42835 | F16: 87000 | G16: B | H16: =DATEDIF(E16,TODAY(),"Y")
A17: EMP10016 | B17: 賴子豪 | C17: 財務部 | D17: L3 | E17: 41580 | F17: 84000 | G17: A | H17: =DATEDIF(E17,TODAY(),"Y")
A18: EMP10017 | B18: 謝冠宇 | C18: 工程部 | D18: L3 | E18: 43482 | F18: 73000 | G18: B | H18: =DATEDIF(E18,TODAY(),"Y")
A19: EMP10018 | B19: 賴宗霖 | C19: 業務部 | D19: L4 | E19: 41503 | F19: 94000 | G19: B | H19: =DATEDIF(E19,TODAY(),"Y") | I19: 43213
A20: EMP10019 | B20: 高俊廷 | C20: 工程部 | D20: L2 | E20: 41994 | F20: 54000 | G20: B | H20: =DATEDIF(E20,TODAY(),"Y")
A21: EMP10020 | B21: 蘇美玲 | C21: 工程部 | D21: L5 | E21: 44498 | F21: 121000 | G21: B | H21: =DATEDIF(E21,TODAY(),"Y")
A22: EMP10021 | B22: 葉宗霖 | C22: 人資部 | D22: L3 | E22: 45452 | F22: 85000 | G22: B | H22: =DATEDIF(E22,TODAY(),"Y")
A23: EMP10022 | B23: 李淑芬 | C23: 工程部 | D23: L6 | E23: 41785 | F23: 139000 | G23: B | H23: =DATEDIF(E23,TODAY(),"Y")
A24: EMP10023 | B24: 羅峻豪 | C24: 工程部 | D24: L3 | E24: 42576 | F24: 71000 | G24: C | H24: =DATEDIF(E24,TODAY(),"Y")
A25: EMP10024 | B25: 何淑芬 | C25: 業務部 | D25: L3 | E25: 41325 | F25: 73000 | G25: D | H25: =DATEDIF(E25,TODAY(),"Y") | I25: 42675
A26: EMP10025 | B26: 郭蕙如 | C26: 法務部 | D26: L2 | E26: 43054 | F26: 58000 | G26: C | H26: =DATEDIF(E26,TODAY(),"Y")
A27: EMP10026 | B27: 蘇敏慧 | C27: 人資部 | D27: L4 | E27: 41525 | F27: 102000 | G27: A | H27: =DATEDIF(E27,TODAY(),"Y")
A28: EMP10027 | B28: 林美玲 | C28: 工程部 | D28: L3 | E28: 42122 | F28: 76000 | G28: B | H28: =DATEDIF(E28,TODAY(),"Y")
A29: EMP10028 | B29: 葉宗霖 | C29: 行銷部 | D29: L3 | E29: 42629 | F29: 66000 | G29: C | H29: =DATEDIF(E29,TODAY(),"Y")
A30: EMP10029 | B30: 莊敏慧 | C30: 工程部 | D30: L3 | E30: 44238 | F30: 82000 | G30: C | H30: =DATEDIF(E30,TODAY(),"Y")
A31: EMP10030 | B31: 陳佩珊 | C31: 法務部 | D31: L5 | E31: 42359 | F31: 117000 | G31: C | H31: =DATEDIF(E31,TODAY(),"Y")
A32: EMP10031 | B32: 羅雅菁 | C32: 工程部 | D32: L4 | E32: 44281 | F32: 95000 | G32: C | H32: =DATEDIF(E32,TODAY(),"Y")
A33: EMP10032 | B33: 林奕辰 | C33: 業務部 | D33: L4 | E33: 41794 | F33: 93000 | G33: B | H33: =DATEDIF(E33,TODAY(),"Y")
A34: EMP10033 | B34: 葉俊傑 | C34: 工程部 | D34: L2 | E34: 42773 | F34: 62000 | G34: B | H34: =DATEDIF(E34,TODAY(),"Y")
A35: EMP10034 | B35: 曾怡君 | C35: 工程部 | D35: L3 | E35: 43195 | F35: 73000 | G35: C | H35: =DATEDIF(E35,TODAY(),"Y")
A36: EMP10035 | B36: 王瑞玲 | C36: 人資部 | D36: L4 | E36: 41135 | F36: 102000 | G36: B | H36: =DATEDIF(E36,TODAY(),"Y") | I36: 42155
A37: EMP10036 | B37: 江柏翰 | C37: 產品部 | D37: L6 | E37: 44468 | F37: 143000 | G37: A | H37: =DATEDIF(E37,TODAY(),"Y")
A38: EMP10037 | B38: 蘇淑貞 | C38: 產品部 | D38: L3 | E38: 42466 | F38: 81000 | G38: A | H38: =DATEDIF(E38,TODAY(),"Y")
A39: EMP10038 | B39: 蕭馨儀 | C39: 法務部 | D39: L1 | E39: 41482 | F39: 38000 | G39: B | H39: =DATEDIF(E39,TODAY(),"Y")
A40: EMP10039 | B40: 葉冠霖 | C40: 工程部 | D40: L4 | E40: 43369 | F40: 106000 | G40: C | H40: =DATEDIF(E40,TODAY(),"Y")
...

Sheet 薪資統計
A1: 部門 | B1: 人數 | C1: 平均月薪 | D1: 最高月薪 | E1: 最低月薪 | F1: 薪資中位數
A2: 工程部 | B2: =COUNTIF(員工資料!C:C,A2) | C2: =IFERROR(AVERAGEIF(員工資料!C:C,A2,員工資料!F:F),0) | D2: =IFERROR(MAXIFS(員工資料!F:F,員工資料!C:C,A2),0) | E2: =IFERROR(MINIFS(員工資料!F:F,員工資料!C:C,A2),0) | F2: =IFERROR(AVERAGEIF(員工資料!C:C,A2,員工資料!F:F),0)
A3: 產品部 | B3: =COUNTIF(員工資料!C:C,A3) | C3: =IFERROR(AVERAGEIF(員工資料!C:C,A3,員工資料!F:F),0) | D3: =IFERROR(MAXIFS(員工資料!F:F,員工資料!C:C,A3),0) | E3: =IFERROR(MINIFS(員工資料!F:F,員工資料!C:C,A3),0) | F3: =IFERROR(AVERAGEIF(員工資料!C:C,A3,員工資料!F:F),0)
A4: 行銷部 | B4: =COUNTIF(員工資料!C:C,A4) | C4: =IFERROR(AVERAGEIF(員工資料!C:C,A4,員工資料!F:F),0) | D4: =IFERROR(MAXIFS(員工資料!F:F,員工資料!C:C,A4),0) | E4: =IFERROR(MINIFS(員工資料!F:F,員工資料!C:C,A4),0) | F4: =IFERROR(AVERAGEIF(員工資料!C:C,A4,員工資料!F:F),0)
A5: 業務部 | B5: =COUNTIF(員工資料!C:C,A5) | C5: =IFERROR(AVERAGEIF(員工資料!C:C,A5,員工資料!F:F),0) | D5: =IFERROR(MAXIFS(員工資料!F:F,員工資料!C:C,A5),0) | E5: =IFERROR(MINIFS(員工資料!F:F,員工資料!C:C,A5),0) | F5: =IFERROR(AVERAGEIF(員工資料!C:C,A5,員工資料!F:F),0)
A6: 人資部 | B6: =COUNTIF(員工資料!C:C,A6) | C6: =IFERROR(AVERAGEIF(員工資料!C:C,A6,員工資料!F:F),0) | D6: =IFERROR(MAXIFS(員工資料!F:F,員工資料!C:C,A6),0) | E6: =IFERROR(MINIFS(員工資料!F:F,員工資料!C:C,A6),0) | F6: =IFERROR(AVERAGEIF(員工資料!C:C,A6,員工資料!F:F),0)
A7: 財務部 | B7: =COUNTIF(員工資料!C:C,A7) | C7: =IFERROR(AVERAGEIF(員工資料!C:C,A7,員工資料!F:F),0) | D7: =IFERROR(MAXIFS(員工資料!F:F,員工資料!C:C,A7),0) | E7: =IFERROR(MINIFS(員工資料!F:F,員工資料!C:C,A7),0) | F7: =IFERROR(AVERAGEIF(員工資料!C:C,A7,員工資料!F:F),0)
A8: 法務部 | B8: =COUNTIF(員工資料!C:C,A8) | C8: =IFERROR(AVERAGEIF(員工資料!C:C,A8,員工資料!F:F),0) | D8: =IFERROR(MAXIFS(員工資料!F:F,員工資料!C:C,A8),0) | E8: =IFERROR(MINIFS(員工資料!F:F,員工資料!C:C,A8),0) | F8: =IFERROR(AVERAGEIF(員工資料!C:C,A8,員工資料!F:F),0)
A9: 全體合計 | B9: =SUM(B2:B8) | C9: =AVERAGE(員工資料!F2:F201) | D9: =MAX(員工資料!F2:F201) | E9: =MIN(員工資料!F2:F201) | F9: =MEDIAN(員工資料!F2:F201)

Sheet 績效分布
A1: 部門 | B1: A級人數 | C1: B級人數 | D1: C級人數 | E1: D級人數 | F1: 總人數 | G1: A率% | H1: B率%
A2: 工程部 | B2: =COUNTIFS(員工資料!C:C,A2,員工資料!G:G,"A") | C2: =COUNTIFS(員工資料!C:C,A2,員工資料!G:G,"B") | D2: =COUNTIFS(員工資料!C:C,A2,員工資料!G:G,"C") | E2: =COUNTIFS(員工資料!C:C,A2,員工資料!G:G,"D") | F2: =SUM(B2:E2) | G2: =IFERROR(B2/F2,0) | H2: =IFERROR(C2/F2,0)
A3: 產品部 | B3: =COUNTIFS(員工資料!C:C,A3,員工資料!G:G,"A") | C3: =COUNTIFS(員工資料!C:C,A3,員工資料!G:G,"B") | D3: =COUNTIFS(員工資料!C:C,A3,員工資料!G:G,"C") | E3: =COUNTIFS(員工資料!C:C,A3,員工資料!G:G,"D") | F3: =SUM(B3:E3) | G3: =IFERROR(B3/F3,0) | H3: =IFERROR(C3/F3,0)
A4: 行銷部 | B4: =COUNTIFS(員工資料!C:C,A4,員工資料!G:G,"A") | C4: =COUNTIFS(員工資料!C:C,A4,員工資料!G:G,"B") | D4: =COUNTIFS(員工資料!C:C,A4,員工資料!G:G,"C") | E4: =COUNTIFS(員工資料!C:C,A4,員工資料!G:G,"D") | F4: =SUM(B4:E4) | G4: =IFERROR(B4/F4,0) | H4: =IFERROR(C4/F4,0)
A5: 業務部 | B5: =COUNTIFS(員工資料!C:C,A5,員工資料!G:G,"A") | C5: =COUNTIFS(員工資料!C:C,A5,員工資料!G:G,"B") | D5: =COUNTIFS(員工資料!C:C,A5,員工資料!G:G,"C") | E5: =COUNTIFS(員工資料!C:C,A5,員工資料!G:G,"D") | F5: =SUM(B5:E5) | G5: =IFERROR(B5/F5,0) | H5: =IFERROR(C5/F5,0)
A6: 人資部 | B6: =COUNTIFS(員工資料!C:C,A6,員工資料!G:G,"A") | C6: =COUNTIFS(員工資料!C:C,A6,員工資料!G:G,"B") | D6: =COUNTIFS(員工資料!C:C,A6,員工資料!G:G,"C") | E6: =COUNTIFS(員工資料!C:C,A6,員工資料!G:G,"D") | F6: =SUM(B6:E6) | G6: =IFERROR(B6/F6,0) | H6: =IFERROR(C6/F6,0)
A7: 財務部 | B7: =COUNTIFS(員工資料!C:C,A7,員工資料!G:G,"A") | C7: =COUNTIFS(員工資料!C:C,A7,員工資料!G:G,"B") | D7: =COUNTIFS(員工資料!C:C,A7,員工資料!G:G,"C") | E7: =COUNTIFS(員工資料!C:C,A7,員工資料!G:G,"D") | F7: =SUM(B7:E7) | G7: =IFERROR(B7/F7,0) | H7: =IFERROR(C7/F7,0)
A8: 法務部 | B8: =COUNTIFS(員工資料!C:C,A8,員工資料!G:G,"A") | C8: =COUNTIFS(員工資料!C:C,A8,員工資料!G:G,"B") | D8: =COUNTIFS(員工資料!C:C,A8,員工資料!G:G,"C") | E8: =COUNTIFS(員工資料!C:C,A8,員工資料!G:G,"D") | F8: =SUM(B8:E8) | G8: =IFERROR(B8/F8,0) | H8: =IFERROR(C8/F8,0)
A9: 全體 | B9: =COUNTIF(員工資料!G:G,"A") | C9: =COUNTIF(員工資料!G:G,"B") | D9: =COUNTIF(員工資料!G:G,"C") | E9: =COUNTIF(員工資料!G:G,"D") | F9: =SUM(B9:E9) | G9: =IFERROR(B9/F9,0) | H9: =IFERROR(C9/F9,0)
